ts_recv,ts_event,rtype,publisher_id,instrument_id,action,side,depth,price,size,flags,ts_in_delta,sequence,bid_px_00,ask_px_00,bid_sz_00,ask_sz_00,bid_ct_00,ask_ct_00,bid_px_01,ask_px_01,bid_sz_01,ask_sz_01,bid_ct_01,ask_ct_01,bid_px_02,ask_px_02,bid_sz_02,ask_sz_02,bid_ct_02,ask_ct_02,bid_px_03,ask_px_03,bid_sz_03,ask_sz_03,bid_ct_03,ask_ct_03,bid_px_04,ask_px_04,bid_sz_04,ask_sz_04,bid_ct_04,ask_ct_04,bid_px_05,ask_px_05,bid_sz_05,ask_sz_05,bid_ct_05,ask_ct_05,bid_px_06,ask_px_06,bid_sz_06,ask_sz_06,bid_ct_06,ask_ct_06,bid_px_07,ask_px_07,bid_sz_07,ask_sz_07,bid_ct_07,ask_ct_07,bid_px_08,ask_px_08,bid_sz_08,ask_sz_08,bid_ct_08,ask_ct_08,bid_px_09,ask_px_09,bid_sz_09,ask_sz_09,bid_ct_09,ask_ct_09,symbol
2025-01-02T09:00:00.002340541Z,2025-01-02T09:00:00.002173888Z,10,2,16244,A,N,0,418.37,1,130,166653,282667,,418.37,0,1,0,1,,,0,0,0,0,,,0,0,0,0,,,0,0,0,0,,,0,0,0,0,,,0,0,0,0,,,0,0,0,0,,,0,0,0,0,,,0,0,0,0,,,0,0,0,0,TSLA
2025-01-02T09:00:00.021087009Z,2025-01-02T09:00:00.020920418Z,10,2,38,A,N,0,236.33,40,130,166591,283085,236.33,,40,0,1,0,,,0,0,0,0,,,0,0,0,0,,,0,0,0,0,,,0,0,0,0,,,0,0,0,0,,,0,0,0,0,,,0,0,0,0,,,0,0,0,0,,,0,0,0,0,AAPL
2025-01-02T09:00:00.021736941Z,2025-01-02T09:00:00.021570013Z,10,2,16244,A,A,1,436.45,175,130,166928,283107,,418.37,0,1,0,1,,436.45,0,175,0,1,,,0,0,0,0,,,0,0,0,0,,,0,0,0,0,,,0,0,0,0,,,0,0,0,0,,,0,0,0,0,,,0,0,0,0,,,0,0,0,0,TSLA
2025-01-02T09:00:00.022959521Z,2025-01-02T09:00:00.022792976Z,10,2,16244,A,B,0,405.1,500,130,166545,283129,405.1,418.37,500,1,1,1,,436.45,0,175,0,1,,,0,0,0,0,,,0,0,0,0,,,0,0,0,0,,,0,0,0,0,,,0,0,0,0,,,0,0,0,0,,,0,0,0,0,,,0,0,0,0,TSLA
2025-01-02T09:00:00.052863937Z,2025-01-02T09:00:00.052684493Z,10,2,16244,A,A,1,960,25,128,179444,283305,405.1,418.37,500,1,1,1,,432.68,0,1,0,1,,436.45,0,175,0,1,,960,0,25,0,1,,,0,0,0,0,,,0,0,0,0,,,0,0,0,0,,,0,0,0,0,,,0,0,0,0,,,0,0,0,0,TSLA
2025-01-02T09:00:00.052883442Z,2025-01-02T09:00:00.052705243Z,10,2,16244,A,B,1,367.93,24,130,178199,283333,405.1,418.37,500,1,1,1,367.93,432.68,24,1,1,1,,436.45,0,175,0,1,,960,0,25,0,1,,,0,0,0,0,,,0,0,0,0,,,0,0,0,0,,,0,0,0,0,,,0,0,0,0,,,0,0,0,0,TSLA
2025-01-02T09:00:00.085809212Z,2025-01-02T09:00:00.085640796Z,10,2,780,A,N,0,259.76,25,130,168416,284545,259.76,,25,0,1,0,,,0,0,0,0,,,0,0,0,0,,,0,0,0,0,,,0,0,0,0,,,0,0,0,0,,,0,0,0,0,,,0,0,0,0,,,0,0,0,0,,,0,0,0,0,AMGN
2025-01-02T09:00:00.085851917Z,2025-01-02T09:00:00.085676444Z,10,2,780,A,A,0,263.84,25,130,175473,284552,259.76,263.84,25,25,1,1,,,0,0,0,0,,,0,0,0,0,,,0,0,0,0,,,0,0,0,0,,,0,0,0,0,,,0,0,0,0,,,0,0,0,0,,,0,0,0,0,,,0,0,0,0,AMGN
2025-01-02T09:00:00.100732988Z,2025-01-02T09:00:00.100566523Z,10,2,38,A,B,0,251.1,400,130,166465,285157,251.1,,400,0,1,0,236.33,,40,0,1,0,,,0,0,0,0,,,0,0,0,0,,,0,0,0,0,,,0,0,0,0,,,0,0,0,0,,,0,0,0,0,,,0,0,0,0,,,0,0,0,0,AAPL
2025-01-02T09:00:00.100749424Z,2025-01-02T09:00:00.100580325Z,10,2,38,A,A,0,251.51,200,130,169099,285158,251.1,251.51,400,200,1,1,236.33,,40,0,1,0,,,0,0,0,0,,,0,0,0,0,,,0,0,0,0,,,0,0,0,0,,,0,0,0,0,,,0,0,0,0,,,0,0,0,0,,,0,0,0,0,AAPL
2025-01-02T09:00:00.100964244Z,2025-01-02T09:00:00.100795913Z,10,2,16244,A,B,0,408.04,50,130,168331,285171,408.04,418.37,50,1,1,1,405.1,432.68,500,1,1,1,367.93,436.45,24,175,1,1,,960,0,25,0,1,,,0,0,0,0,,,0,0,0,0,,,0,0,0,0,,,0,0,0,0,,,0,0,0,0,,,0,0,0,0,TSLA
2025-01-02T09:00:00.100974645Z,2025-01-02T09:00:00.100808337Z,10,2,16244,A,A,0,408.63,100,130,166308,285172,408.04,408.63,50,100,1,1,405.1,418.37,500,1,1,1,367.93,432.68,24,1,1,1,,436.45,0,175,0,1,,960,0,25,0,1,,,0,0,0,0,,,0,0,0,0,,,0,0,0,0,,,0,0,0,0,,,0,0,0,0,TSLA
2025-01-02T09:00:00.101579492Z,2025-01-02T09:00:00.101412860Z,10,2,38,C,B,0,251.1,400,130,166632,285215,236.33,251.51,40,200,1,1,,,0,0,0,0,,,0,0,0,0,,,0,0,0,0,,,0,0,0,0,,,0,0,0,0,,,0,0,0,0,,,0,0,0,0,,,0,0,0,0,,,0,0,0,0,AAPL
2025-01-02T09:00:00.102905535Z,2025-01-02T09:00:00.102739767Z,10,2,16244,C,A,0,408.63,100,130,165768,285318,408.04,418.37,50,1,1,1,405.1,432.68,500,1,1,1,367.93,436.45,24,175,1,1,,960,0,25,0,1,,,0,0,0,0,,,0,0,0,0,,,0,0,0,0,,,0,0,0,0,,,0,0,0,0,,,0,0,0,0,TSLA
2025-01-02T09:00:00.103063377Z,2025-01-02T09:00:00.102895443Z,10,2,16244,A,B,0,408.04,50,130,167934,285327,408.04,418.37,100,1,2,1,405.1,432.68,500,1,1,1,367.93,436.45,24,175,1,1,,960,0,25,0,1,,,0,0,0,0,,,0,0,0,0,,,0,0,0,0,,,0,0,0,0,,,0,0,0,0,,,0,0,0,0,TSLA
2025-01-02T09:00:00.103288058Z,2025-01-02T09:00:00.103122268Z,10,2,16244,C,B,0,408.04,50,130,165790,285343,408.04,418.37,50,1,1,1,405.1,432.68,500,1,1,1,367.93,436.45,24,175,1,1,,960,0,25,0,1,,,0,0,0,0,,,0,0,0,0,,,0,0,0,0,,,0,0,0,0,,,0,0,0,0,,,0,0,0,0,TSLA
2025-01-02T09:00:00.103306437Z,2025-01-02T09:00:00.103137912Z,10,2,16244,C,B,0,408.04,50,130,168525,285344,405.1,418.37,500,1,1,1,367.93,432.68,24,1,1,1,,436.45,0,175,0,1,,960,0,25,0,1,,,0,0,0,0,,,0,0,0,0,,,0,0,0,0,,,0,0,0,0,,,0,0,0,0,,,0,0,0,0,TSLA
2025-01-02T09:00:00.104177228Z,2025-01-02T09:00:00.104009883Z,10,2,38,C,A,0,251.51,200,130,167345,285400,236.33,,40,0,1,0,,,0,0,0,0,,,0,0,0,0,,,0,0,0,0,,,0,0,0,0,,,0,0,0,0,,,0,0,0,0,,,0,0,0,0,,,0,0,0,0,,,0,0,0,0,AAPL
2025-01-02T09:00:00.104939677Z,2025-01-02T09:00:00.104772562Z,10,2,780,A,B,0,259.93,25,130,167115,285443,259.93,263.84,25,25,1,1,,,0,0,0,0,,,0,0,0,0,,,0,0,0,0,,,0,0,0,0,,,0,0,0,0,,,0,0,0,0,,,0,0,0,0,,,0,0,0,0,,,0,0,0,0,AMGN
2025-01-02T09:00:00.104962561Z,2025-01-02T09:00:00.104793802Z,10,2,780,A,A,0,263.33,25,130,168759,285444,259.93,263.33,25,25,1,1,,,0,0,0,0,,,0,0,0,0,,,0,0,0,0,,,0,0,0,0,,,0,0,0,0,,,0,0,0,0,,,0,0,0,0,,,0,0,0,0,,,0,0,0,0,AMGN
2025-01-02T09:00:00.108499925Z,2025-01-02T09:00:00.108332500Z,10,2,16244,A,B,0,408.05,100,130,167425,285658,408.05,418.37,100,1,1,1,405.1,432.68,500,1,1,1,367.93,436.45,24,175,1,1,,960,0,25,0,1,,,0,0,0,0,,,0,0,0,0,,,0,0,0,0,,,0,0,0,0,,,0,0,0,0,,,0,0,0,0,TSLA
2025-01-02T09:00:00.114684530Z,2025-01-02T09:00:00.114518141Z,10,2,780,A,B,0,260.27,25,130,166389,285765,260.27,263.33,25,25,1,1,,,0,0,0,0,,,0,0,0,0,,,0,0,0,0,,,0,0,0,0,,,0,0,0,0,,,0,0,0,0,,,0,0,0,0,,,0,0,0,0,,,0,0,0,0,AMGN
2025-01-02T09:00:00.117931074Z,2025-01-02T09:00:00.117764777Z,10,2,16244,A,B,0,408.26,50,130,166297,285840,408.26,418.37,50,1,1,1,405.1,432.68,500,1,1,1,367.93,436.45,24,175,1,1,,960,0,25,0,1,,,0,0,0,0,,,0,0,0,0,,,0,0,0,0,,,0,0,0,0,,,0,0,0,0,,,0,0,0,0,TSLA
2025-01-02T09:00:00.141078816Z,2025-01-02T09:00:00.140912150Z,10,2,16244,C,B,0,408.26,50,130,166666,286220,405.1,418.37,500,1,1,1,367.93,432.68,24,1,1,1,,436.45,0,175,0,1,,960,0,25,0,1,,,0,0,0,0,,,0,0,0,0,,,0,0,0,0,,,0,0,0,0,,,0,0,0,0,,,0,0,0,0,TSLA
2025-01-02T09:00:00.183135710Z,2025-01-02T09:00:00.182968387Z,10,2,16244,A,B,2,350,11,130,167323,286764,405.1,418.37,500,1,1,1,367.93,432.68,24,1,1,1,350,436.45,11,175,1,1,,960,0,25,0,1,,,0,0,0,0,,,0,0,0,0,,,0,0,0,0,,,0,0,0,0,,,0,0,0,0,,,0,0,0,0,TSLA
2025-01-02T09:00:00.214214236Z,2025-01-02T09:00:00.214047479Z,10,2,38,A,A,0,271.27,4,130,166757,287108,236.33,271.27,40,4,1,1,,,0,0,0,0,,,0,0,0,0,,,0,0,0,0,,,0,0,0,0,,,0,0,0,0,,,0,0,0,0,,,0,0,0,0,,,0,0,0,0,,,0,0,0,0,AAPL
2025-01-02T09:00:00.214290081Z,2025-01-02T09:00:00.214123000Z,10,2,38,A,A,1,296.36,3,130,167081,287110,236.33,271.27,40,4,1,1,,296.36,0,3,0,1,,,0,0,0,0,,,0,0,0,0,,,0,0,0,0,,,0,0,0,0,,,0,0,0,0,,,0,0,0,0,,,0,0,0,0,,,0,0,0,0,AAPL
2025-01-02T09:00:00.306637161Z,2025-01-02T09:00:00.306470767Z,10,2,16244,A,B,3,192.6,10,130,166394,287957,405.1,418.37,500,1,1,1,367.93,432.68,24,1,1,1,350,436.45,11,175,1,1,192.6,960,10,25,1,1,,,0,0,0,0,,,0,0,0,0,,,0,0,0,0,,,0,0,0,0,,,0,0,0,0,,,0,0,0,0,TSLA
2025-01-02T09:00:00.581583124Z,2025-01-02T09:00:00.581416652Z,10,2,16244,A,B,1,376.17,5,130,166472,289530,405.1,418.37,500,1,1,1,376.17,432.68,5,1,1,1,367.93,436.45,24,175,1,1,350,960,11,25,1,1,192.6,,10,0,1,0,,,0,0,0,0,,,0,0,0,0,,,0,0,0,0,,,0,0,0,0,,,0,0,0,0,TSLA
2025-01-02T09:00:00.587128183Z,2025-01-02T09:00:00.586961619Z,10,2,16244,A,B,1,403.55,247,130,166564,289555,405.1,418.37,500,1,1,1,403.55,432.68,247,1,1,1,376.17,436.45,5,175,1,1,367.93,960,24,25,1,1,350,,11,0,1,0,192.6,,10,0,1,0,,,0,0,0,0,,,0,0,0,0,,,0,0,0,0,,,0,0,0,0,TSLA
2025-01-02T09:00:00.587289525Z,2025-01-02T09:00:00.587122920Z,10,2,16244,A,A,0,414.19,247,130,166605,289556,405.1,414.19,500,247,1,1,403.55,418.37,247,1,1,1,376.17,432.68,5,1,1,1,367.93,436.45,24,175,1,1,350,960,11,25,1,1,192.6,,10,0,1,0,,,0,0,0,0,,,0,0,0,0,,,0,0,0,0,,,0,0,0,0,TSLA
2025-01-02T09:00:00.588398795Z,2025-01-02T09:00:00.588232383Z,10,2,16244,A,B,5,320,500,130,166412,289565,405.1,414.19,500,247,1,1,403.55,418.37,247,1,1,1,376.17,432.68,5,1,1,1,367.93,436.45,24,175,1,1,350,960,11,25,1,1,320,,500,0,1,0,192.6,,10,0,1,0,,,0,0,0,0,,,0,0,0,0,,,0,0,0,0,TSLA
2025-01-02T09:00:00.588863338Z,2025-01-02T09:00:00.588697006Z,10,2,16244,A,A,4,489.96,100,130,166332,289572,405.1,414.19,500,247,1,1,403.55,418.37,247,1,1,1,376.17,432.68,5,1,1,1,367.93,436.45,24,175,1,1,350,489.96,11,100,1,1,320,960,500,25,1,1,192.6,,10,0,1,0,,,0,0,0,0,,,0,0,0,0,,,0,0,0,0,TSLA
2025-01-02T09:00:00.589327960Z,2025-01-02T09:00:00.589161675Z,10,2,16244,A,B,2,400,100,130,166285,289577,405.1,414.19,500,247,1,1,403.55,418.37,247,1,1,1,400,432.68,100,1,1,1,376.17,436.45,5,175,1,1,367.93,489.96,24,100,1,1,350,960,11,25,1,1,320,,500,0,1,0,192.6,,10,0,1,0,,,0,0,0,0,,,0,0,0,0,TSLA
2025-01-02T09:00:00.652337326Z,2025-01-02T09:00:00.652170588Z,10,2,16244,A,B,7,310.1,50,130,166738,289780,405.1,414.19,500,247,1,1,403.55,418.37,247,1,1,1,400,432.68,100,1,1,1,376.17,436.45,5,175,1,1,367.93,489.96,24,100,1,1,350,960,11,25,1,1,320,,500,0,1,0,310.1,,50,0,1,0,192.6,,10,0,1,0,,,0,0,0,0,TSLA
2025-01-02T09:00:00.652799144Z,2025-01-02T09:00:00.652632412Z,10,2,16244,A,A,4,455.58,50,130,166732,289787,405.1,414.19,500,247,1,1,403.55,418.37,247,1,1,1,400,432.68,100,1,1,1,376.17,436.45,5,175,1,1,367.93,455.58,24,50,1,1,350,489.96,11,100,1,1,320,960,500,25,1,1,310.1,,50,0,1,0,192.6,,10,0,1,0,,,0,0,0,0,TSLA
2025-01-02T09:00:00.653526460Z,2025-01-02T09:00:00.653359765Z,10,2,16244,A,B,2,400.14,1,130,166695,289791,405.1,414.19,500,247,1,1,403.55,418.37,247,1,1,1,400.14,432.68,1,1,1,1,400,436.45,100,175,1,1,376.17,455.58,5,50,1,1,367.93,489.96,24,100,1,1,350,960,11,25,1,1,320,,500,0,1,0,310.1,,50,0,1,0,192.6,,10,0,1,0,TSLA
2025-01-02T09:00:00.667459306Z,2025-01-02T09:00:00.667290935Z,10,2,16244,A,N,0,410.4,500,130,168371,289840,407.2,410.4,500,500,1,1,405.1,414.19,500,247,1,1,403.55,418.37,247,1,1,1,400.14,432.68,1,1,1,1,400,436.45,100,175,1,1,376.17,455.58,5,50,1,1,367.93,489.96,24,100,1,1,350,960,11,25,1,1,320,,500,0,1,0,310.1,,50,0,1,0,TSLA
2025-01-02T09:00:00.676082836Z,2025-01-02T09:00:00.675916258Z,10,2,16244,A,B,5,376.27,5,130,166578,289858,407.2,410.4,500,500,1,1,405.1,414.19,500,247,1,1,403.55,418.37,247,1,1,1,400.14,432.68,1,1,1,1,400,436.45,100,175,1,1,376.27,455.58,5,50,1,1,376.17,489.96,5,100,1,1,367.93,960,24,25,1,1,350,,11,0,1,0,320,,500,0,1,0,TSLA
2025-01-02T09:00:00.677991630Z,2025-01-02T09:00:00.677825208Z,10,2,16244,A,B,1,405.8,500,130,166422,289867,407.2,410.4,500,500,1,1,405.8,414.19,500,247,1,1,405.1,418.37,500,1,1,1,403.55,432.68,247,1,1,1,400.14,436.45,1,175,1,1,400,455.58,100,50,1,1,376.27,489.96,5,100,1,1,376.17,960,5,25,1,1,367.93,,24,0,1,0,350,,11,0,1,0,TSLA
2025-01-02T09:00:00.678062053Z,2025-01-02T09:00:00.677895726Z,10,2,16244,A,A,5,445,10,130,166327,289868,407.2,410.4,500,500,1,1,405.8,414.19,500,247,1,1,405.1,418.37,500,1,1,1,403.55,432.68,247,1,1,1,400.14,436.45,1,175,1,1,400,445,100,10,1,1,376.27,455.58,5,50,1,1,376.17,489.96,5,100,1,1,367.93,960,24,25,1,1,350,,11,0,1,0,TSLA
2025-01-02T09:00:00.681868485Z,2025-01-02T09:00:00.681702050Z,10,2,16244,A,B,6,396.12,1,130,166435,289883,407.2,410.4,500,500,1,1,405.8,414.19,500,247,1,1,405.1,418.37,500,1,1,1,403.55,432.68,247,1,1,1,400.14,436.45,1,175,1,1,400,445,100,10,1,1,396.12,455.58,1,50,1,1,376.27,489.96,5,100,1,1,376.17,960,5,25,1,1,367.93,,24,0,1,0,TSLA
2025-01-02T09:00:00.682230585Z,2025-01-02T09:00:00.682063963Z,10,2,16244,A,A,7,460,10,130,166622,289884,407.2,410.4,500,500,1,1,405.8,414.19,500,247,1,1,405.1,418.37,500,1,1,1,403.55,432.68,247,1,1,1,400.14,436.45,1,175,1,1,400,445,100,10,1,1,396.12,455.58,1,50,1,1,376.27,460,5,10,1,1,376.17,489.96,5,100,1,1,367.93,960,24,25,1,1,TSLA
2025-01-02T09:00:00.727825822Z,2025-01-02T09:00:00.727659255Z,10,2,38,A,B,0,248.18,399,130,166567,290013,248.18,271.27,399,4,1,1,236.33,296.36,40,3,1,1,,,0,0,0,0,,,0,0,0,0,,,0,0,0,0,,,0,0,0,0,,,0,0,0,0,,,0,0,0,0,,,0,0,0,0,,,0,0,0,0,AAPL
2025-01-02T09:00:00.727907549Z,2025-01-02T09:00:00.727741030Z,10,2,38,A,A,0,254.7,399,130,166519,290014,248.18,254.7,399,399,1,1,236.33,271.27,40,4,1,1,,296.36,0,3,0,1,,,0,0,0,0,,,0,0,0,0,,,0,0,0,0,,,0,0,0,0,,,0,0,0,0,,,0,0,0,0,,,0,0,0,0,AAPL
2025-01-02T09:00:00.743706313Z,2025-01-02T09:00:00.743540363Z,10,2,16244,C,A,0,410.4,500,130,165950,290135,407.2,414.19,500,247,1,1,405.8,418.37,500,1,1,1,405.1,432.68,500,1,1,1,403.55,436.45,247,175,1,1,400.14,445,1,10,1,1,400,455.58,100,50,1,1,396.12,460,1,10,1,1,376.27,489.96,5,100,1,1,376.17,960,5,25,1,1,367.93,,24,0,1,0,TSLA
2025-01-02T09:00:00.755303610Z,2025-01-02T09:00:00.755137069Z,10,2,16244,A,A,4,442.88,3,130,166541,290165,407.2,414.19,500,247,1,1,405.8,418.37,500,1,1,1,405.1,432.68,500,1,1,1,403.55,436.45,247,175,1,1,400.14,442.88,1,3,1,1,400,445,100,10,1,1,396.12,455.58,1,50,1,1,376.27,460,5,10,1,1,376.17,489.96,5,100,1,1,367.93,960,24,25,1,1,TSLA
2025-01-02T09:00:00.756163600Z,2025-01-02T09:00:00.755996981Z,10,2,16244,A,A,0,410.6,500,130,166619,290171,407.2,410.6,500,500,1,1,405.8,414.19,500,247,1,1,405.1,418.37,500,1,1,1,403.55,432.68,247,1,1,1,400.14,436.45,1,175,1,1,400,442.88,100,3,1,1,396.12,445,1,10,1,1,376.27,455.58,5,50,1,1,376.17,460,5,10,1,1,367.93,489.96,24,100,1,1,TSLA
2025-01-02T09:00:00.813335273Z,2025-01-02T09:00:00.813169052Z,10,2,16244,C,A,0,410.6,500,130,166221,290329,407.2,414.19,500,247,1,1,405.1,418.37,500,1,1,1,403.55,432.68,247,1,1,1,400.14,436.45,1,175,1,1,400,442.88,100,3,1,1,396.12,445,1,10,1,1,376.27,455.58,5,50,1,1,376.17,460,5,10,1,1,367.93,489.96,24,100,1,1,350,960,11,25,1,1,TSLA
2025-01-02T09:00:00.849718938Z,2025-01-02T09:00:00.849552666Z,10,2,16244,A,B,1,405.8,500,130,166272,290456,407.2,414.19,500,247,1,1,405.8,418.37,500,1,1,1,405.1,432.68,500,1,1,1,403.55,436.45,247,175,1,1,400.14,442.88,1,3,1,1,400,445,100,10,1,1,396.12,455.58,1,50,1,1,376.27,460,5,10,1,1,376.17,489.96,5,100,1,1,367.93,960,24,25,1,1,TSLA
2025-01-02T09:00:00.859330921Z,2025-01-02T09:00:00.859164183Z,10,2,16244,A,A,0,411.4,500,130,166738,290482,407.2,411.4,500,500,1,1,405.8,414.19,500,247,1,1,405.1,418.37,500,1,1,1,403.55,432.68,247,1,1,1,400.14,436.45,1,175,1,1,400,442.88,100,3,1,1,396.12,445,1,10,1,1,376.27,455.58,5,50,1,1,376.17,460,5,10,1,1,367.93,489.96,24,100,1,1,TSLA
2025-01-02T09:00:00.882366567Z,2025-01-02T09:00:00.882200217Z,10,2,16244,A,A,0,410.6,500,130,166350,290597,407.2,410.6,500,500,1,1,405.8,411.4,500,500,1,1,405.1,414.19,500,247,1,1,403.55,418.37,247,1,1,1,400.14,432.68,1,1,1,1,400,436.45,100,175,1,1,396.12,442.88,1,3,1,1,376.27,445,5,10,1,1,376.17,455.58,5,50,1,1,367.93,460,24,10,1,1,TSLA
2025-01-02T09:00:00.882501860Z,2025-01-02T09:00:00.882335884Z,10,2,16244,C,A,1,411.4,500,130,165976,290600,407.2,410.6,500,500,1,1,405.8,414.19,500,247,1,1,405.1,418.37,500,1,1,1,403.55,432.68,247,1,1,1,400.14,436.45,1,175,1,1,400,442.88,100,3,1,1,396.12,445,1,10,1,1,376.27,455.58,5,50,1,1,376.17,460,5,10,1,1,367.93,489.96,24,100,1,1,TSLA
2025-01-02T09:00:00.910452882Z,2025-01-02T09:00:00.910286260Z,10,2,16244,C,B,0,407.2,500,130,166622,290677,405.8,410.6,500,500,1,1,405.1,414.19,500,247,1,1,403.55,418.37,247,1,1,1,400.14,432.68,1,1,1,1,400,436.45,100,175,1,1,396.12,442.88,1,3,1,1,376.27,445,5,10,1,1,376.17,455.58,5,50,1,1,367.93,460,24,10,1,1,350,489.96,11,100,1,1,TSLA
2025-01-02T09:00:00.916342432Z,2025-01-02T09:00:00.916175869Z,10,2,16244,A,A,0,410.4,500,130,166563,290703,405.8,410.4,500,500,1,1,405.1,410.6,500,500,1,1,403.55,414.19,247,247,1,1,400.14,418.37,1,1,1,1,400,432.68,100,1,1,1,396.12,436.45,1,175,1,1,376.27,442.88,5,3,1,1,376.17,445,5,10,1,1,367.93,455.58,24,50,1,1,350,460,11,10,1,1,TSLA
2025-01-02T09:00:00.916502927Z,2025-01-02T09:00:00.916336721Z,10,2,16244,C,A,1,410.6,500,130,166206,290705,405.8,410.4,500,500,1,1,405.1,414.19,500,247,1,1,403.55,418.37,247,1,1,1,400.14,432.68,1,1,1,1,400,436.45,100,175,1,1,396.12,442.88,1,3,1,1,376.27,445,5,10,1,1,376.17,455.58,5,50,1,1,367.93,460,24,10,1,1,350,489.96,11,100,1,1,TSLA
2025-01-02T09:00:00.920236975Z,2025-01-02T09:00:00.920070585Z,10,2,16244,A,B,1,405.6,500,130,166390,290717,405.8,410.4,500,500,1,1,405.6,414.19,500,247,1,1,405.1,418.37,500,1,1,1,403.55,432.68,247,1,1,1,400.14,436.45,1,175,1,1,400,442.88,100,3,1,1,396.12,445,1,10,1,1,376.27,455.58,5,50,1,1,376.17,460,5,10,1,1,367.93,489.96,24,100,1,1,TSLA
2025-01-02T09:00:00.925099509Z,2025-01-02T09:00:00.924933203Z,10,2,16244,A,B,0,407,500,130,166306,290738,407,410.4,500,500,1,1,405.8,414.19,500,247,1,1,405.6,418.37,500,1,1,1,405.1,432.68,500,1,1,1,403.55,436.45,247,175,1,1,400.14,442.88,1,3,1,1,400,445,100,10,1,1,396.12,455.58,1,50,1,1,376.27,460,5,10,1,1,376.17,489.96,5,100,1,1,TSLA
2025-01-02T09:00:00.925874984Z,2025-01-02T09:00:00.925708209Z,10,2,16244,C,B,1,405.8,500,130,166775,290740,407,410.4,500,500,1,1,405.6,414.19,500,247,1,1,405.1,418.37,500,1,1,1,403.55,432.68,247,1,1,1,400.14,436.45,1,175,1,1,400,442.88,100,3,1,1,396.12,445,1,10,1,1,376.27,455.58,5,50,1,1,376.17,460,5,10,1,1,367.93,489.96,24,100,1,1,TSLA
2025-01-02T09:00:00.957074263Z,2025-01-02T09:00:00.956907261Z,10,2,38,A,B,2,200,5,130,167002,290855,248.18,254.7,399,399,1,1,236.33,271.27,40,4,1,1,200,296.36,5,3,1,1,,,0,0,0,0,,,0,0,0,0,,,0,0,0,0,,,0,0,0,0,,,0,0,0,0,,,0,0,0,0,,,0,0,0,0,AAPL
2025-01-02T09:00:00.957558854Z,2025-01-02T09:00:00.957392604Z,10,2,38,A,B,3,147.6,100,130,166250,290856,248.18,254.7,399,399,1,1,236.33,271.27,40,4,1,1,200,296.36,5,3,1,1,147.6,,100,0,1,0,,,0,0,0,0,,,0,0,0,0,,,0,0,0,0,,,0,0,0,0,,,0,0,0,0,,,0,0,0,0,AAPL
2025-01-02T09:00:00.980037925Z,2025-01-02T09:00:00.979871673Z,10,2,16244,A,A,0,409.3,22,130,166252,290910,407,409.3,500,22,1,1,405.6,410.4,500,500,1,1,405.1,414.19,500,247,1,1,403.55,418.37,247,1,1,1,400.14,432.68,1,1,1,1,400,436.45,100,175,1,1,396.12,442.88,1,3,1,1,376.27,445,5,10,1,1,376.17,455.58,5,50,1,1,367.93,460,24,10,1,1,TSLA
2025-01-02T09:00:00.980062965Z,2025-01-02T09:00:00.979896738Z,10,2,16244,A,B,0,408.22,23,130,166227,290911,408.22,409.3,23,22,1,1,407,410.4,500,500,1,1,405.6,414.19,500,247,1,1,405.1,418.37,500,1,1,1,403.55,432.68,247,1,1,1,400.14,436.45,1,175,1,1,400,442.88,100,3,1,1,396.12,445,1,10,1,1,376.27,455.58,5,50,1,1,376.17,460,5,10,1,1,TSLA
2025-01-02T09:00:00.996713412Z,2025-01-02T09:00:00.996547066Z,10,2,38,A,B,1,245.37,4,130,166346,290945,248.18,254.7,399,399,1,1,245.37,271.27,4,4,1,1,236.33,296.36,40,3,1,1,200,,5,0,1,0,147.6,,100,0,1,0,,,0,0,0,0,,,0,0,0,0,,,0,0,0,0,,,0,0,0,0,,,0,0,0,0,AAPL
2025-01-02T09:00:00.998244936Z,2025-01-02T09:00:00.998078419Z,10,2,780,A,B,1,258.1,25,130,166517,290954,260.27,263.33,25,25,1,1,258.1,,25,0,1,0,,,0,0,0,0,,,0,0,0,0,,,0,0,0,0,,,0,0,0,0,,,0,0,0,0,,,0,0,0,0,,,0,0,0,0,,,0,0,0,0,AMGN
2025-01-02T09:00:01.004832230Z,2025-01-02T09:00:01.004665992Z,10,2,38,A,B,2,237.05,1,130,166238,290989,248.18,254.7,399,399,1,1,245.37,271.27,4,4,1,1,237.05,296.36,1,3,1,1,236.33,,40,0,1,0,200,,5,0,1,0,147.6,,100,0,1,0,,,0,0,0,0,,,0,0,0,0,,,0,0,0,0,,,0,0,0,0,AAPL
2025-01-02T09:00:01.037405448Z,2025-01-02T09:00:01.037239470Z,10,2,16244,C,A,1,410.4,500,130,165978,291128,408.22,409.3,23,22,1,1,407,414.19,500,247,1,1,405.6,418.37,500,1,1,1,405.1,432.68,500,1,1,1,403.55,436.45,247,175,1,1,400.14,442.88,1,3,1,1,400,445,100,10,1,1,396.12,455.58,1,50,1,1,376.27,460,5,10,1,1,376.17,489.96,5,100,1,1,TSLA
2025-01-02T09:00:01.049377490Z,2025-01-02T09:00:01.049211182Z,10,2,16244,A,A,1,410.6,500,130,166308,291194,408.22,409.3,23,22,1,1,407,410.6,500,500,1,1,405.6,414.19,500,247,1,1,405.1,418.37,500,1,1,1,403.55,432.68,247,1,1,1,400.14,436.45,1,175,1,1,400,442.88,100,3,1,1,396.12,445,1,10,1,1,376.27,455.58,5,50,1,1,376.17,460,5,10,1,1,TSLA
2025-01-02T09:00:01.080482288Z,2025-01-02T09:00:01.080315735Z,10,2,38,A,A,0,251.9,120,130,166553,291876,248.18,251.9,399,120,1,1,245.37,254.7,4,399,1,1,237.05,271.27,1,4,1,1,236.33,296.36,40,3,1,1,200,,5,0,1,0,147.6,,100,0,1,0,,,0,0,0,0,,,0,0,0,0,,,0,0,0,0,,,0,0,0,0,AAPL
2025-01-02T09:00:01.146090155Z,2025-01-02T09:00:01.145923142Z,10,2,38,A,B,0,251.17,200,130,167013,292252,251.17,251.9,200,120,1,1,248.18,254.7,399,399,1,1,245.37,271.27,4,4,1,1,237.05,296.36,1,3,1,1,236.33,,40,0,1,0,200,,5,0,1,0,147.6,,100,0,1,0,,,0,0,0,0,,,0,0,0,0,,,0,0,0,0,AAPL
2025-01-02T09:00:01.146139764Z,2025-01-02T09:00:01.145972535Z,10,2,780,A,A,0,262.82,25,130,167229,292256,260.27,262.82,25,25,1,1,258.1,,25,0,1,0,,,0,0,0,0,,,0,0,0,0,,,0,0,0,0,,,0,0,0,0,,,0,0,0,0,,,0,0,0,0,,,0,0,0,0,,,0,0,0,0,AMGN
2025-01-02T09:00:01.147669074Z,2025-01-02T09:00:01.147502698Z,10,2,38,A,A,0,251.48,200,130,166376,292352,251.17,251.48,200,200,1,1,248.18,251.9,399,120,1,1,245.37,254.7,4,399,1,1,237.05,271.27,1,4,1,1,236.33,296.36,40,3,1,1,200,,5,0,1,0,147.6,,100,0,1,0,,,0,0,0,0,,,0,0,0,0,,,0,0,0,0,AAPL
2025-01-02T09:00:01.148239895Z,2025-01-02T09:00:01.148073684Z,10,2,16244,A,B,1,408.01,50,130,166211,292393,408.22,409.3,23,22,1,1,408.01,410.6,50,500,1,1,407,414.19,500,247,1,1,405.6,418.37,500,1,1,1,405.1,432.68,500,1,1,1,403.55,436.45,247,175,1,1,400.14,442.88,1,3,1,1,400,445,100,10,1,1,396.12,455.58,1,50,1,1,376.27,460,5,10,1,1,TSLA
2025-01-02T09:00:01.148355040Z,2025-01-02T09:00:01.148187148Z,10,2,16244,A,A,0,408.86,50,130,167892,292402,408.22,408.86,23,50,1,1,408.01,409.3,50,22,1,1,407,410.6,500,500,1,1,405.6,414.19,500,247,1,1,405.1,418.37,500,1,1,1,403.55,432.68,247,1,1,1,400.14,436.45,1,175,1,1,400,442.88,100,3,1,1,396.12,445,1,10,1,1,376.27,455.58,5,50,1,1,TSLA
2025-01-02T09:00:01.151912740Z,2025-01-02T09:00:01.151745908Z,10,2,16244,A,B,0,408.69,36,130,166832,292439,408.69,408.86,36,50,1,1,408.22,409.3,23,22,1,1,408.01,410.6,50,500,1,1,407,414.19,500,247,1,1,405.6,418.37,500,1,1,1,405.1,432.68,500,1,1,1,403.55,436.45,247,175,1,1,400.14,442.88,1,3,1,1,400,445,100,10,1,1,396.12,455.58,1,50,1,1,TSLA
2025-01-02T09:00:01.176615409Z,2025-01-02T09:00:01.176449135Z,10,2,16244,A,A,2,410.4,500,130,166274,292638,408.69,408.86,36,50,1,1,408.22,409.3,23,22,1,1,408.01,410.4,50,500,1,1,407,410.6,500,500,1,1,405.6,414.19,500,247,1,1,405.1,418.37,500,1,1,1,403.55,432.68,247,1,1,1,400.14,436.45,1,175,1,1,400,442.88,100,3,1,1,396.12,445,1,10,1,1,TSLA
2025-01-02T09:00:01.180196840Z,2025-01-02T09:00:01.180030996Z,10,2,16244,C,A,2,410.4,500,130,165844,292660,408.69,408.86,36,50,1,1,408.22,409.3,23,22,1,1,408.01,410.6,50,500,1,1,407,414.19,500,247,1,1,405.6,418.37,500,1,1,1,405.1,432.68,500,1,1,1,403.55,436.45,247,175,1,1,400.14,442.88,1,3,1,1,400,445,100,10,1,1,396.12,455.58,1,50,1,1,TSLA
2025-01-02T09:00:01.180634325Z,2025-01-02T09:00:01.180465711Z,10,2,16244,T,A,0,408.69,36,130,168614,292662,408.69,408.86,36,50,1,1,408.22,409.3,23,22,1,1,408.01,410.6,50,500,1,1,407,414.19,500,247,1,1,405.6,418.37,500,1,1,1,405.1,432.68,500,1,1,1,403.55,436.45,247,175,1,1,400.14,442.88,1,3,1,1,400,445,100,10,1,1,396.12,455.58,1,50,1,1,TSLA
2025-01-02T09:00:01.180634325Z,2025-01-02T09:00:01.180465711Z,10,2,16244,C,B,0,408.69,36,130,168614,292662,408.22,408.86,23,50,1,1,408.01,409.3,50,22,1,1,407,410.6,500,500,1,1,405.6,414.19,500,247,1,1,405.1,418.37,500,1,1,1,403.55,432.68,247,1,1,1,400.14,436.45,1,175,1,1,400,442.88,100,3,1,1,396.12,445,1,10,1,1,376.27,455.58,5,50,1,1,TSLA
2025-01-02T09:00:01.180659105Z,2025-01-02T09:00:01.180492610Z,10,2,16244,A,A,0,408.78,26,130,166495,292664,408.22,408.78,23,26,1,1,408.01,408.86,50,50,1,1,407,409.3,500,22,1,1,405.6,410.6,500,500,1,1,405.1,414.19,500,247,1,1,403.55,418.37,247,1,1,1,400.14,432.68,1,1,1,1,400,436.45,100,175,1,1,396.12,442.88,1,3,1,1,376.27,445,5,10,1,1,TSLA
2025-01-02T09:00:01.180671644Z,2025-01-02T09:00:01.180505397Z,10,2,16244,A,A,1,408.83,26,130,166247,292665,408.22,408.78,23,26,1,1,408.01,408.83,50,26,1,1,407,408.86,500,50,1,1,405.6,409.3,500,22,1,1,405.1,410.6,500,500,1,1,403.55,414.19,247,247,1,1,400.14,418.37,1,1,1,1,400,432.68,100,1,1,1,396.12,436.45,1,175,1,1,376.27,442.88,5,3,1,1,TSLA
2025-01-02T09:00:01.180678151Z,2025-01-02T09:00:01.180512396Z,10,2,16244,C,B,1,408.01,50,130,165755,292666,408.22,408.78,23,26,1,1,407,408.83,500,26,1,1,405.6,408.86,500,50,1,1,405.1,409.3,500,22,1,1,403.55,410.6,247,500,1,1,400.14,414.19,1,247,1,1,400,418.37,100,1,1,1,396.12,432.68,1,1,1,1,376.27,436.45,5,175,1,1,376.17,442.88,5,3,1,1,TSLA
2025-01-02T09:00:01.181222711Z,2025-01-02T09:00:01.181055962Z,10,2,38,A,B,5,202.75,10,130,166749,292671,251.17,251.48,200,200,1,1,248.18,251.9,399,120,1,1,245.37,254.7,4,399,1,1,237.05,271.27,1,4,1,1,236.33,296.36,40,3,1,1,202.75,,10,0,1,0,200,,5,0,1,0,147.6,,100,0,1,0,,,0,0,0,0,,,0,0,0,0,AAPL
2025-01-02T09:00:01.193190573Z,2025-01-02T09:00:01.193024813Z,10,2,16244,C,A,1,408.83,26,130,165760,292739,408.22,408.78,23,26,1,1,407,408.86,500,50,1,1,405.6,409.3,500,22,1,1,405.1,410.6,500,500,1,1,403.55,414.19,247,247,1,1,400.14,418.37,1,1,1,1,400,432.68,100,1,1,1,396.12,436.45,1,175,1,1,376.27,442.88,5,3,1,1,376.17,445,5,10,1,1,TSLA
2025-01-02T09:00:01.193709953Z,2025-01-02T09:00:01.193543605Z,10,2,38,A,A,2,254,20,130,166348,292744,251.17,251.48,200,200,1,1,248.18,251.9,399,120,1,1,245.37,254,4,20,1,1,237.05,254.7,1,399,1,1,236.33,271.27,40,4,1,1,202.75,296.36,10,3,1,1,200,,5,0,1,0,147.6,,100,0,1,0,,,0,0,0,0,,,0,0,0,0,AAPL
2025-01-02T09:00:01.195058107Z,2025-01-02T09:00:01.194891097Z,10,2,16244,A,B,1,407.2,500,130,167010,292752,408.22,408.78,23,26,1,1,407.2,408.86,500,50,1,1,407,409.3,500,22,1,1,405.6,410.6,500,500,1,1,405.1,414.19,500,247,1,1,403.55,418.37,247,1,1,1,400.14,432.68,1,1,1,1,400,436.45,100,175,1,1,396.12,442.88,1,3,1,1,376.27,445,5,10,1,1,TSLA
2025-01-02T09:00:01.197552351Z,2025-01-02T09:00:01.197386275Z,10,2,16244,C,B,2,407,500,130,166076,292774,408.22,408.78,23,26,1,1,407.2,408.86,500,50,1,1,405.6,409.3,500,22,1,1,405.1,410.6,500,500,1,1,403.55,414.19,247,247,1,1,400.14,418.37,1,1,1,1,400,432.68,100,1,1,1,396.12,436.45,1,175,1,1,376.27,442.88,5,3,1,1,376.17,445,5,10,1,1,TSLA
2025-01-02T09:00:01.207888710Z,2025-01-02T09:00:01.207722671Z,10,2,16244,C,B,1,407.2,500,130,166039,292812,408.22,408.78,23,26,1,1,405.6,408.86,500,50,1,1,405.1,409.3,500,22,1,1,403.55,410.6,247,500,1,1,400.14,414.19,1,247,1,1,400,418.37,100,1,1,1,396.12,432.68,1,1,1,1,376.27,436.45,5,175,1,1,376.17,442.88,5,3,1,1,367.93,445,24,10,1,1,TSLA
2025-01-02T09:00:01.207898156Z,2025-01-02T09:00:01.207731189Z,10,2,16244,A,A,3,410.4,500,130,166967,292813,408.22,408.78,23,26,1,1,405.6,408.86,500,50,1,1,405.1,409.3,500,22,1,1,403.55,410.4,247,500,1,1,400.14,410.6,1,500,1,1,400,414.19,100,247,1,1,396.12,418.37,1,1,1,1,376.27,432.68,5,1,1,1,376.17,436.45,5,175,1,1,367.93,442.88,24,3,1,1,TSLA
2025-01-02T09:00:01.211315120Z,2025-01-02T09:00:01.211148618Z,10,2,16244,C,A,4,410.6,500,130,166502,292821,408.22,408.78,23,26,1,1,405.6,408.86,500,50,1,1,405.1,409.3,500,22,1,1,403.55,410.4,247,500,1,1,400.14,414.19,1,247,1,1,400,418.37,100,1,1,1,396.12,432.68,1,1,1,1,376.27,436.45,5,175,1,1,376.17,442.88,5,3,1,1,367.93,445,24,10,1,1,TSLA
2025-01-02T09:00:01.223966018Z,2025-01-02T09:00:01.223799811Z,10,2,38,A,A,4,267.73,5,130,166207,292869,251.17,251.48,200,200,1,1,248.18,251.9,399,120,1,1,245.37,254,4,20,1,1,237.05,254.7,1,399,1,1,236.33,267.73,40,5,1,1,202.75,271.27,10,4,1,1,200,296.36,5,3,1,1,147.6,,100,0,1,0,,,0,0,0,0,,,0,0,0,0,AAPL
2025-01-02T09:00:01.225899973Z,2025-01-02T09:00:01.225733734Z,10,2,38,A,B,3,238.44,5,130,166239,292878,251.17,251.48,200,200,1,1,248.18,251.9,399,120,1,1,245.37,254,4,20,1,1,238.44,254.7,5,399,1,1,237.05,267.73,1,5,1,1,236.33,271.27,40,4,1,1,202.75,296.36,10,3,1,1,200,,5,0,1,0,147.6,,100,0,1,0,,,0,0,0,0,AAPL
2025-01-02T09:00:01.233590326Z,2025-01-02T09:00:01.233424013Z,10,2,16244,C,A,1,408.86,50,130,166313,292921,408.22,408.78,23,26,1,1,405.6,409.3,500,22,1,1,405.1,410.4,500,500,1,1,403.55,414.19,247,247,1,1,400.14,418.37,1,1,1,1,400,432.68,100,1,1,1,396.12,436.45,1,175,1,1,376.27,442.88,5,3,1,1,376.17,445,5,10,1,1,367.93,455.58,24,50,1,1,TSLA
2025-01-02T09:00:01.233609056Z,2025-01-02T09:00:01.233443082Z,10,2,16244,C,A,0,408.78,26,130,165974,292922,408.22,409.3,23,22,1,1,405.6,410.4,500,500,1,1,405.1,414.19,500,247,1,1,403.55,418.37,247,1,1,1,400.14,432.68,1,1,1,1,400,436.45,100,175,1,1,396.12,442.88,1,3,1,1,376.27,445,5,10,1,1,376.17,455.58,5,50,1,1,367.93,460,24,10,1,1,TSLA
2025-01-02T09:00:01.245388487Z,2025-01-02T09:00:01.245221801Z,10,2,16244,A,N,1,410.2,500,130,166686,292971,408.22,409.3,23,22,1,1,407,410.2,500,500,1,1,405.6,410.4,500,500,1,1,405.1,414.19,500,247,1,1,403.55,418.37,247,1,1,1,400.14,432.68,1,1,1,1,400,436.45,100,175,1,1,396.12,442.88,1,3,1,1,376.27,445,5,10,1,1,376.17,455.58,5,50,1,1,TSLA
2025-01-02T09:00:01.245650825Z,2025-01-02T09:00:01.245484200Z,10,2,3572,A,N,0,1007.73,10,130,166625,292972,,1007.73,0,10,0,1,,,0,0,0,0,,,0,0,0,0,,,0,0,0,0,,,0,0,0,0,,,0,0,0,0,,,0,0,0,0,,,0,0,0,0,,,0,0,0,0,,,0,0,0,0,COST
2025-01-02T09:00:01.247685693Z,2025-01-02T09:00:01.247519559Z,10,2,16244,C,A,2,410.4,500,130,166134,292981,408.22,409.3,23,22,1,1,407,410.2,500,500,1,1,405.6,414.19,500,247,1,1,405.1,418.37,500,1,1,1,403.55,432.68,247,1,1,1,400.14,436.45,1,175,1,1,400,442.88,100,3,1,1,396.12,445,1,10,1,1,376.27,455.58,5,50,1,1,376.17,460,5,10,1,1,TSLA
2025-01-02T09:00:01.257374687Z,2025-01-02T09:00:01.257208625Z,10,2,16244,A,B,2,405.8,500,130,166062,293008,408.22,409.3,23,22,1,1,407,410.2,500,500,1,1,405.8,414.19,500,247,1,1,405.6,418.37,500,1,1,1,405.1,432.68,500,1,1,1,403.55,436.45,247,175,1,1,400.14,442.88,1,3,1,1,400,445,100,10,1,1,396.12,455.58,1,50,1,1,376.27,460,5,10,1,1,TSLA
2025-01-02T09:00:01.257517176Z,2025-01-02T09:00:01.257351150Z,10,2,16244,C,B,3,405.6,500,130,166026,293009,408.22,409.3,23,22,1,1,407,410.2,500,500,1,1,405.8,414.19,500,247,1,1,405.1,418.37,500,1,1,1,403.55,432.68,247,1,1,1,400.14,436.45,1,175,1,1,400,442.88,100,3,1,1,396.12,445,1,10,1,1,376.27,455.58,5,50,1,1,376.17,460,5,10,1,1,TSLA